GPU available: True (cuda), used: True
TPU available: False, using: 0 TPU cores
IPU available: False, using: 0 IPUs
HPU available: False, using: 0 HPUs
LOCAL_RANK: 0 - CUDA_VISIBLE_DEVICES: [0]
  | Name    | Type               | Params
-----------------------------------------------
0 | loss_fn | CrossEntropyLoss   | 0
1 | metric  | MulticlassAccuracy | 0
2 | layer   | Sequential         | 449 K
3 | fc      | Sequential         | 660
-----------------------------------------------
450 K     Trainable params
0         Non-trainable params
450 K     Total params
1.802     Total estimated model params size (MB)
Exception ignored in: <function _releaseLock at 0x14d986094670>
Traceback (most recent call last):
  File "/software/spackages/linux-rocky8-x86_64/gcc-9.5.0/anaconda3-2022.05-zyrazrj6uvrtukupqzhaslr63w7hj6in/envs/pytorch_workshop/lib/python3.10/logging/__init__.py", line 228, in _releaseLock